<mujoco>
  <option gravity="0 0 -10"/>

  <worldbody>
    <light name="light" mode="targetbody" target="last link" directional="true" pos="1 1 3" />
    <geom name='floor' pos='0 0 0' size='2.5 2.5 0.1'  type='plane'/>
    <!--robot-->
    <body name="last link" pos="0 0 0.8">
        <inertial pos="0 0 0" mass="1" diaginertia="0.1 0.1 0.1" />
        <geom type="box" pos="0 0 0" size="0.1 0.1 0.1" rgba="1 0 0 1"/>
        <joint type="slide" axis="1 0 0"/>
        <body name="gripper" pos="0 0 -0.2">
            <inertial pos="0 0 0" mass="1" diaginertia="0 0 0" />
            <geom type="box" pos="0 0 0" size="0.1 0.1 0.1" rgba="0 1 0 1"/>
            <site name="sensor" pos="0 0 -0.1" rgba="1 0 0 0" size="0.01 0.01 0.01" type="box"/>
        </body>
    </body>
    <!--object-->
    <body name="box" pos="0 0 0.3">
        <inertial pos="0 0 0" mass="4" diaginertia="0.1 0.1 0.1" />
        <geom type="box" size="0.1 0.1 0.1"  rgba="0 0 1 1"/>
        <joint type="free"/>
    </body>
  </worldbody>

  <equality>
      <connect name="test" active="true" body1="gripper" body2="box" anchor="0 0 0"/>
  </equality>

  <sensor>
      <force name="force" site="sensor"/>
  </sensor>
</mujoco>